============================= test session starts ==============================
platform linux -- Python 3.12.8, pytest-7.4.3, pluggy-1.6.0 -- /home/ubuntu/EM_test_project/venv/bin/python
cachedir: .pytest_cache
rootdir: /home/ubuntu/EM_test_project
plugins: mock-3.12.0, asyncio-0.23.2, anyio-4.9.0, cov-4.1.0
asyncio: mode=Mode.STRICT
collecting ... collected 22 items

tests/api/v1/test_base_endpoints.py::test_root_endpoint PASSED           [  4%]
tests/api/v1/test_base_endpoints.py::test_health_check_endpoint PASSED   [  9%]
tests/api/v1/endpoints/test_auth.py::test_register_user PASSED           [ 13%]
tests/api/v1/endpoints/test_auth.py::test_register_duplicate_user PASSED [ 18%]
tests/api/v1/endpoints/test_auth.py::test_login_for_access_token PASSED  [ 22%]
tests/api/v1/endpoints/test_auth.py::test_login_with_invalid_credentials PASSED [ 27%]
tests/api/v1/endpoints/test_items.py::test_create_item_endpoint PASSED   [ 31%]
tests/api/v1/endpoints/test_items.py::test_get_items_endpoint PASSED     [ 36%]
tests/api/v1/endpoints/test_items.py::test_get_item_endpoint PASSED      [ 40%]
tests/api/v1/endpoints/test_items.py::test_get_nonexistent_item_endpoint PASSED [ 45%]
tests/api/v1/endpoints/test_items.py::test_update_item_endpoint PASSED   [ 50%]
tests/api/v1/endpoints/test_items.py::test_delete_item_endpoint PASSED   [ 54%]
tests/api/v1/endpoints/test_llm.py::test_chat_with_ai PASSED             [ 59%]
tests/api/v1/endpoints/test_llm.py::test_chat_with_ai_unauthorized PASSED [ 63%]
tests/api/v1/endpoints/test_llm.py::test_chat_with_ai_invalid_request PASSED [ 68%]
tests/api/v1/endpoints/test_llm.py::test_chat_with_ai_api_key_not_set PASSED [ 72%]
tests/api/v1/endpoints/test_llm.py::test_chat_with_ai_performance PASSED [ 77%]
tests/api/v1/endpoints/test_llm.py::test_masui_introduction PASSED       [ 81%]
tests/utils/test_middleware_and_utils.py::test_logging_middleware PASSED [ 86%]
tests/utils/test_middleware_and_utils.py::test_cors_settings PASSED      [ 90%]
tests/utils/test_middleware_and_utils.py::test_settings_loading PASSED   [ 95%]
tests/utils/test_middleware_and_utils.py::test_jwt_token_verification PASSED [100%]

=============================== warnings summary ===============================
app/db/session.py:23
  /home/ubuntu/EM_test_project/app/db/session.py:23: MovedIn20Warning: The ``declarative_base()`` function is now available as sqlalchemy.orm.declarative_base(). (deprecated since: 2.0) (Background on SQLAlchemy 2.0 at: https://sqlalche.me/e/b8d9)
    Base = declarative_base()

venv/lib/python3.12/site-packages/passlib/utils/__init__.py:854
  /home/ubuntu/EM_test_project/venv/lib/python3.12/site-packages/passlib/utils/__init__.py:854: DeprecationWarning: 'crypt' is deprecated and slated for removal in Python 3.13
    from crypt import crypt as _crypt

venv/lib/python3.12/site-packages/pydantic/_internal/_config.py:323
venv/lib/python3.12/site-packages/pydantic/_internal/_config.py:323
venv/lib/python3.12/site-packages/pydantic/_internal/_config.py:323
  /home/ubuntu/EM_test_project/venv/lib/python3.12/site-packages/pydantic/_internal/_config.py:323: PydanticDeprecatedSince20: Support for class-based `config` is deprecated, use ConfigDict instead. Deprecated in Pydantic V2.0 to be removed in V3.0. See Pydantic V2 Migration Guide at https://errors.pydantic.dev/2.11/migration/
    warnings.warn(DEPRECATION_MESSAGE, DeprecationWarning)

venv/lib/python3.12/site-packages/pydantic/fields.py:1076
venv/lib/python3.12/site-packages/pydantic/fields.py:1076
venv/lib/python3.12/site-packages/pydantic/fields.py:1076
  /home/ubuntu/EM_test_project/venv/lib/python3.12/site-packages/pydantic/fields.py:1076: PydanticDeprecatedSince20: Using extra keyword arguments on `Field` is deprecated and will be removed. Use `json_schema_extra` instead. (Extra keys: 'env'). Deprecated in Pydantic V2.0 to be removed in V3.0. See Pydantic V2 Migration Guide at https://errors.pydantic.dev/2.11/migration/
    warn(

tests/api/v1/test_base_endpoints.py::test_root_endpoint
  /home/ubuntu/EM_test_project/venv/lib/python3.12/site-packages/_pytest/python.py:198: PytestReturnNotNoneWarning: Expected None, but tests/api/v1/test_base_endpoints.py::test_root_endpoint returned {'test_id': 'BASE-001', 'status': '成功', 'execution_time': 0.0023636817932128906, 'details': 'ルートエンドポイントが正常に応答しました。'}, which will be an error in a future version of pytest.  Did you mean to use `assert` instead of `return`?
    warnings.warn(

tests/api/v1/test_base_endpoints.py::test_health_check_endpoint
  /home/ubuntu/EM_test_project/venv/lib/python3.12/site-packages/_pytest/python.py:198: PytestReturnNotNoneWarning: Expected None, but tests/api/v1/test_base_endpoints.py::test_health_check_endpoint returned {'test_id': 'BASE-002', 'status': '成功', 'execution_time': 0.0019195079803466797, 'details': 'ヘルスチェックエンドポイントが正常に応答しました。'}, which will be an error in a future version of pytest.  Did you mean to use `assert` instead of `return`?
    warnings.warn(

tests/api/v1/endpoints/test_auth.py::test_register_user
  /home/ubuntu/EM_test_project/venv/lib/python3.12/site-packages/_pytest/python.py:198: PytestReturnNotNoneWarning: Expected None, but tests/api/v1/endpoints/test_auth.py::test_register_user returned {'test_id': 'AUTH-001', 'status': '成功', 'execution_time': 0.28472161293029785, 'details': '新規ユーザーが正常に登録されました。'}, which will be an error in a future version of pytest.  Did you mean to use `assert` instead of `return`?
    warnings.warn(

tests/api/v1/endpoints/test_auth.py::test_register_duplicate_user
  /home/ubuntu/EM_test_project/venv/lib/python3.12/site-packages/_pytest/python.py:198: PytestReturnNotNoneWarning: Expected None, but tests/api/v1/endpoints/test_auth.py::test_register_duplicate_user returned {'test_id': 'AUTH-002', 'status': '成功', 'execution_time': 0.0047245025634765625, 'details': '既存のユーザー名で登録を試みた際に適切なエラーが返されました。'}, which will be an error in a future version of pytest.  Did you mean to use `assert` instead of `return`?
    warnings.warn(

tests/api/v1/endpoints/test_auth.py::test_login_for_access_token
tests/utils/test_middleware_and_utils.py::test_jwt_token_verification
  /home/ubuntu/EM_test_project/app/utils/auth.py:67: DeprecationWarning: datetime.datetime.utcnow() is deprecated and scheduled for removal in a future version. Use timezone-aware objects to represent datetimes in UTC: datetime.datetime.now(datetime.UTC).
    expire = datetime.utcnow() + expires_delta

tests/api/v1/endpoints/test_auth.py::test_login_for_access_token
  /home/ubuntu/EM_test_project/venv/lib/python3.12/site-packages/_pytest/python.py:198: PytestReturnNotNoneWarning: Expected None, but tests/api/v1/endpoints/test_auth.py::test_login_for_access_token returned {'test_id': 'AUTH-003', 'status': '成功', 'execution_time': 0.27901577949523926, 'details': '有効な認証情報でJWTトークンが正常に取得できました。'}, which will be an error in a future version of pytest.  Did you mean to use `assert` instead of `return`?
    warnings.warn(

tests/api/v1/endpoints/test_auth.py::test_login_with_invalid_credentials
  /home/ubuntu/EM_test_project/venv/lib/python3.12/site-packages/_pytest/python.py:198: PytestReturnNotNoneWarning: Expected None, but tests/api/v1/endpoints/test_auth.py::test_login_with_invalid_credentials returned {'test_id': 'AUTH-004', 'status': '成功', 'execution_time': 0.2734718322753906, 'details': '無効なパスワードで適切な認証エラーが返されました。'}, which will be an error in a future version of pytest.  Did you mean to use `assert` instead of `return`?
    warnings.warn(

tests/api/v1/endpoints/test_items.py: 6 warnings
tests/api/v1/endpoints/test_llm.py: 5 warnings
  /home/ubuntu/EM_test_project/app/utils/auth.py:69: DeprecationWarning: datetime.datetime.utcnow() is deprecated and scheduled for removal in a future version. Use timezone-aware objects to represent datetimes in UTC: datetime.datetime.now(datetime.UTC).
    expire = datetime.utcnow() + timedelta(minutes=ACCESS_TOKEN_EXPIRE_MINUTES)

tests/api/v1/endpoints/test_items.py::test_create_item_endpoint
  /home/ubuntu/EM_test_project/venv/lib/python3.12/site-packages/_pytest/python.py:198: PytestReturnNotNoneWarning: Expected None, but tests/api/v1/endpoints/test_items.py::test_create_item_endpoint returned {'test_id': 'ITEM-001', 'status': '成功', 'execution_time': 0.010595083236694336, 'details': 'アイテムが正常に作成されました。'}, which will be an error in a future version of pytest.  Did you mean to use `assert` instead of `return`?
    warnings.warn(

tests/api/v1/endpoints/test_items.py::test_get_items_endpoint
  /home/ubuntu/EM_test_project/venv/lib/python3.12/site-packages/_pytest/python.py:198: PytestReturnNotNoneWarning: Expected None, but tests/api/v1/endpoints/test_items.py::test_get_items_endpoint returned {'test_id': 'ITEM-002', 'status': '成功', 'execution_time': 0.005629777908325195, 'details': 'アイテム一覧が正常に取得されました。アイテム数: 1'}, which will be an error in a future version of pytest.  Did you mean to use `assert` instead of `return`?
    warnings.warn(

tests/api/v1/endpoints/test_items.py::test_get_item_endpoint
  /home/ubuntu/EM_test_project/venv/lib/python3.12/site-packages/_pytest/python.py:198: PytestReturnNotNoneWarning: Expected None, but tests/api/v1/endpoints/test_items.py::test_get_item_endpoint returned {'test_id': 'ITEM-003', 'status': '成功', 'execution_time': 0.005409955978393555, 'details': 'アイテムID 1 が正常に取得されました。'}, which will be an error in a future version of pytest.  Did you mean to use `assert` instead of `return`?
    warnings.warn(

tests/api/v1/endpoints/test_items.py::test_get_nonexistent_item_endpoint
  /home/ubuntu/EM_test_project/venv/lib/python3.12/site-packages/_pytest/python.py:198: PytestReturnNotNoneWarning: Expected None, but tests/api/v1/endpoints/test_items.py::test_get_nonexistent_item_endpoint returned {'test_id': 'ITEM-004', 'status': '成功', 'execution_time': 0.006117343902587891, 'details': '存在しないアイテムIDに対して適切なエラーが返されました。'}, which will be an error in a future version of pytest.  Did you mean to use `assert` instead of `return`?
    warnings.warn(

tests/api/v1/endpoints/test_items.py::test_update_item_endpoint
  /home/ubuntu/EM_test_project/venv/lib/python3.12/site-packages/_pytest/python.py:198: PytestReturnNotNoneWarning: Expected None, but tests/api/v1/endpoints/test_items.py::test_update_item_endpoint returned {'test_id': 'ITEM-005', 'status': '成功', 'execution_time': 0.008372068405151367, 'details': 'アイテムID 1 が正常に更新されました。'}, which will be an error in a future version of pytest.  Did you mean to use `assert` instead of `return`?
    warnings.warn(

tests/api/v1/endpoints/test_items.py::test_delete_item_endpoint
  /home/ubuntu/EM_test_project/venv/lib/python3.12/site-packages/_pytest/python.py:198: PytestReturnNotNoneWarning: Expected None, but tests/api/v1/endpoints/test_items.py::test_delete_item_endpoint returned {'test_id': 'ITEM-006', 'status': '成功', 'execution_time': 0.009971857070922852, 'details': 'アイテムID 1 が正常に削除されました。'}, which will be an error in a future version of pytest.  Did you mean to use `assert` instead of `return`?
    warnings.warn(

tests/api/v1/endpoints/test_llm.py::test_chat_with_ai
  /home/ubuntu/EM_test_project/venv/lib/python3.12/site-packages/_pytest/python.py:198: PytestReturnNotNoneWarning: Expected None, but tests/api/v1/endpoints/test_llm.py::test_chat_with_ai returned {'test_id': 'LLM-001', 'status': '成功', 'execution_time': 0.006059169769287109, 'details': 'AIチャットエンドポイントが正常に応答しました。'}, which will be an error in a future version of pytest.  Did you mean to use `assert` instead of `return`?
    warnings.warn(

tests/api/v1/endpoints/test_llm.py::test_chat_with_ai_unauthorized
  /home/ubuntu/EM_test_project/venv/lib/python3.12/site-packages/_pytest/python.py:198: PytestReturnNotNoneWarning: Expected None, but tests/api/v1/endpoints/test_llm.py::test_chat_with_ai_unauthorized returned {'test_id': 'LLM-002', 'status': '成功', 'execution_time': 0.0034661293029785156, 'details': '未認証ユーザーに対して適切な認証エラーが返されました。'}, which will be an error in a future version of pytest.  Did you mean to use `assert` instead of `return`?
    warnings.warn(

tests/api/v1/endpoints/test_llm.py::test_chat_with_ai_invalid_request
  /home/ubuntu/EM_test_project/venv/lib/python3.12/site-packages/_pytest/python.py:198: PytestReturnNotNoneWarning: Expected None, but tests/api/v1/endpoints/test_llm.py::test_chat_with_ai_invalid_request returned {'test_id': 'LLM-003', 'status': '成功', 'execution_time': 0.0054624080657958984, 'details': '無効なリクエストに対して適切なバリデーションエラーが返されました。'}, which will be an error in a future version of pytest.  Did you mean to use `assert` instead of `return`?
    warnings.warn(

tests/api/v1/endpoints/test_llm.py::test_chat_with_ai_api_key_not_set
  /home/ubuntu/EM_test_project/venv/lib/python3.12/site-packages/_pytest/python.py:198: PytestReturnNotNoneWarning: Expected None, but tests/api/v1/endpoints/test_llm.py::test_chat_with_ai_api_key_not_set returned {'test_id': 'LLM-004', 'status': '成功', 'execution_time': 0.005913972854614258, 'details': 'APIキー未設定時に適切なエラーが返されました。'}, which will be an error in a future version of pytest.  Did you mean to use `assert` instead of `return`?
    warnings.warn(

tests/api/v1/endpoints/test_llm.py::test_chat_with_ai_performance
  /home/ubuntu/EM_test_project/venv/lib/python3.12/site-packages/_pytest/python.py:198: PytestReturnNotNoneWarning: Expected None, but tests/api/v1/endpoints/test_llm.py::test_chat_with_ai_performance returned {'test_id': 'LLM-005', 'status': '成功', 'execution_time': 0.0046234130859375, 'details': '長いプロンプトに対するレスポンス時間は 0.00秒でした。'}, which will be an error in a future version of pytest.  Did you mean to use `assert` instead of `return`?
    warnings.warn(

tests/api/v1/endpoints/test_llm.py::test_masui_introduction
  /home/ubuntu/EM_test_project/venv/lib/python3.12/site-packages/_pytest/python.py:198: PytestReturnNotNoneWarning: Expected None, but tests/api/v1/endpoints/test_llm.py::test_masui_introduction returned {'test_id': 'LLM-006', 'status': '成功', 'execution_time': 0.005451679229736328, 'details': 'AI自己紹介エンドポイントが正常に応答しました。'}, which will be an error in a future version of pytest.  Did you mean to use `assert` instead of `return`?
    warnings.warn(

tests/utils/test_middleware_and_utils.py::test_logging_middleware
  /home/ubuntu/EM_test_project/venv/lib/python3.12/site-packages/_pytest/python.py:198: PytestReturnNotNoneWarning: Expected None, but tests/utils/test_middleware_and_utils.py::test_logging_middleware returned {'test_id': 'UTIL-001', 'status': '成功', 'execution_time': 0.0017588138580322266, 'details': 'リクエストが正しくログに記録されました。'}, which will be an error in a future version of pytest.  Did you mean to use `assert` instead of `return`?
    warnings.warn(

tests/utils/test_middleware_and_utils.py::test_cors_settings
  /home/ubuntu/EM_test_project/venv/lib/python3.12/site-packages/_pytest/python.py:198: PytestReturnNotNoneWarning: Expected None, but tests/utils/test_middleware_and_utils.py::test_cors_settings returned {'test_id': 'UTIL-002', 'status': '成功', 'execution_time': 0.0010368824005126953, 'details': 'CORSヘッダーが正しく設定されています。'}, which will be an error in a future version of pytest.  Did you mean to use `assert` instead of `return`?
    warnings.warn(

tests/utils/test_middleware_and_utils.py::test_settings_loading
  /home/ubuntu/EM_test_project/venv/lib/python3.12/site-packages/_pytest/python.py:198: PytestReturnNotNoneWarning: Expected None, but tests/utils/test_middleware_and_utils.py::test_settings_loading returned {'test_id': 'UTIL-003', 'status': '成功', 'execution_time': 5.9604644775390625e-06, 'details': '設定値が正しく読み込まれています。'}, which will be an error in a future version of pytest.  Did you mean to use `assert` instead of `return`?
    warnings.warn(

tests/utils/test_middleware_and_utils.py::test_jwt_token_verification
  /home/ubuntu/EM_test_project/venv/lib/python3.12/site-packages/_pytest/python.py:198: PytestReturnNotNoneWarning: Expected None, but tests/utils/test_middleware_and_utils.py::test_jwt_token_verification returned {'test_id': 'UTIL-004', 'status': '成功', 'execution_time': 0.005190849304199219, 'details': '期限切れトークンが正しく検証されました。'}, which will be an error in a future version of pytest.  Did you mean to use `assert` instead of `return`?
    warnings.warn(

-- Docs: https://docs.pytest.org/en/stable/how-to/capture-warnings.html
======================= 22 passed, 43 warnings in 6.85s ========================
